Workbook

Sheet Calendrier
B2: Information du collaborateur | K2: 2026 | BF2: Vacances
C3: Entreprise: | D3: HUG | BF3: Scolaire: | DJ3: Date par case | FG3: conditions est-ce un jour ferié | HB3: Congé | IY3: Formation | KV3: Autres | MS3: Récupération | OP3: Congé scolaire | QN3: Malade | SL3: Jour Travaillé
C4: Canton: | D4: GE | E4: pour les jours feriés ( à placer dans la même zone que le choix les vacances scolaires) | BF4: GE
L5: AM | M5: PM | N5: AM | O5: PM | P5: AM | Q5: PM | R5: AM | S5: PM | T5: AM | U5: PM | V5: AM | W5: PM | X5: AM | Y5: PM | AB5: AM | AC5: PM | AD5: AM | AE5: PM | AF5: AM | AG5: PM | AH5: AM | AI5: PM | AJ5: AM | AK5: PM | AL5: AM | AM5: PM | AN5: AM | AO5: PM | AR5: AM | AS5: PM | AT5: AM | AU5: PM | AV5: AM | AW5: PM | AX5: AM | AY5: PM | AZ5: AM | BA5: PM | BB5: AM | BC5: PM | BD5: AM | BE5: PM | DG5: =L10="" -> TRUE
C6: Nom: | D6: Mike | L6: 1 | M6: 1 | N6: 2 | O6: 2 | P6: 3 | Q6: 3 | R6: 4 | S6: 4 | T6: 5 | U6: 5 | V6: 6 | W6: 6 | X6: 7 | Y6: 7 | AB6: 1 | AC6: 1 | AD6: 2 | AE6: 2 | AF6: 3 | AG6: 3 | AH6: 4 | AI6: 4 | AJ6: 5 | AK6: 5 | AL6: 6 | AM6: 6 | AN6: 7 | AO6: 7 | AR6: 1 | AS6: 1 | AT6: 2 | AU6: 2 | AV6: 3 | AW6: 3 | AX6: 4 | AY6: 4 | AZ6: 5 | BA6: 5 | BB6: 6 | BC6: 6 | BD6: 7 | BE6: 7 | DG6: =ISBLANK(L10) -> FALSE
C7: Prenom: | D7: Marek | L7: 1 | M7: 2 | N7: 1 | O7: 2 | P7: 1 | Q7: 2 | R7: 1 | S7: 2 | T7: 1 | U7: 2 | V7: 1 | W7: 2 | X7: 1 | Y7: 2 | AB7: 1 | AC7: 2 | AD7: 1 | AE7: 2 | AF7: 1 | AG7: 2 | AH7: 1 | AI7: 2 | AJ7: 1 | AK7: 2 | AL7: 1 | AM7: 2 | AN7: 1 | AO7: 2 | AR7: 1 | AS7: 2 | AT7: 1 | AU7: 2 | AV7: 1 | AW7: 2 | AX7: 1 | AY7: 2 | AZ7: 1 | BA7: 2 | BB7: 1 | BC7: 2 | BD7: 1 | BE7: 2
K8: 1 | L8: =TEXT(DATE($K$2,K8,1),"mmmm") -> janvier | AA8: 2 | AB8: =TEXT(DATE($K$2,AA8,1),"mmmm") -> février | AQ8: 3 | AR8: =TEXT(DATE($K$2,AQ8,1),"mmmm") -> mars | BJ8: 1 | BK8: janvier | BZ8: 2 | CA8: février | CP8: 3 | CQ8: mars | DG8: 1 | DH8: janvier | DW8: 2 | DX8: février | EM8: 3 | EN8: mars | FE8: janvier | FT8: 2 | FU8: février | GJ8: 3 | GK8: mars | HB8: janvier | HQ8: 2 | HR8: février | IG8: 3 | IH8: mars | IY8: janvier | JN8: 2 | JO8: février | KD8: 3 | KE8: mars | KV8: janvier | LK8: 2 | LL8: février | MA8: 3 | MB8: mars | MS8: janvier | NH8: 2 | NI8: février | NX8: 3 | NY8: mars | OP8: janvier | PE8: 2 | PF8: février | PU8: 3 | PV8: mars | QN8: janvier | RC8: 2 | RD8: février | RS8: 3 | RT8: mars | SL8: janvier | TA8: 2 | TB8: février | TQ8: 3 | TR8: mars
C9: Taux d'activité [%] | D9: 80 | K9: =WEEKDAY(DATE($K$2,K8,1),Parameters!$A$2) -> 4 | L9: =TEXT(2,"jjj") -> lun | N9: =TEXT(3,"jjj") -> mar | P9: =TEXT(4,"jjj") -> mer | R9: =TEXT(5,"jjj") -> jeu | T9: =TEXT(6,"jjj") -> ven | V9: =TEXT(7,"jjj") -> sam | X9: =TEXT(8,"jjj") -> dim | Z9: =DAY(DATE($K$2,K8+1,1)-1) -> 31 | AA9: =WEEKDAY(DATE($K$2,AA8,1),Parameters!$A$2) -> 7 | AB9: =TEXT(2,"jjj") -> lun | AD9: =TEXT(3,"jjj") -> mar | AF9: =TEXT(4,"jjj") -> mer | AH9: =TEXT(5,"jjj") -> jeu | AJ9: =TEXT(6,"jjj") -> ven | AL9: =TEXT(7,"jjj") -> sam | AN9: =TEXT(8,"jjj") -> dim | AP9: =DAY(DATE($K$2,AA8+1,1)-1) -> 28 | AQ9: =WEEKDAY(DATE($K$2,AQ8,1),Parameters!$A$2) -> 7 | AR9: =TEXT(2,"jjj") -> lun | AT9: =TEXT(3,"jjj") -> mar | AV9: =TEXT(4,"jjj") -> mer | AX9: =TEXT(5,"jjj") -> jeu | AZ9: =TEXT(6,"jjj") -> ven | BB9: =TEXT(7,"jjj") -> sam | BD9: =TEXT(8,"jjj") -> dim | BF9: =DAY(DATE($K$2,AQ8+1,1)-1) -> 31 | BJ9: 6 | BK9: lun | BM9: mar | BO9: mer | BQ9: jeu | BS9: ven | BU9: sam | BW9: dim | BY9: 31 | BZ9: 2 | CA9: lun | CC9: mar | CE9: mer | CG9: jeu | CI9: ven | CK9: sam | CM9: dim | CO9: 28 | CP9: 2 | CQ9: lun | CS9: mar | CU9: mer | CW9: jeu | CY9: ven | DA9: sam | DC9: dim | DG9: 6 | DH9: lun | DJ9: mar | DL9: mer | DN9: jeu | DP9: ven | DR9: sam | DT9: dim | DV9: 31 | DW9: 2 | DX9: lun | DZ9: mar | EB9: mer | ED9: jeu | EF9: ven | EH9: sam | EJ9: dim | EL9: 28 | EM9: 2 | EN9: lun | EP9: mar | ER9: mer | ET9: jeu | EV9: ven | EX9: sam | EZ9: dim | FE9: lun | FG9: mar | FI9: mer | FK9: jeu | FM9: ven | FO9: sam | FQ9: dim | FS9: 31 | FT9: 2 | FU9: lun | FW9: mar | FY9: mer | GA9: jeu | GC9: ven | GE9: sam | GG9: dim | GI9: 28 | GJ9: 2 | GK9: lun | GM9: mar | GO9: mer | GQ9: jeu | GS9: ven | GU9: sam | GW9: dim | HB9: lun | HD9: mar | HF9: mer | HH9: jeu | HJ9: ven | HL9: sam | HN9: dim | HP9: 31 | HQ9: 2 | HR9: lun | HT9: mar | HV9: mer | HX9: jeu | HZ9: ven | IB9: sam | ID9: dim | IF9: 28 | IG9: 2 | IH9: lun | IJ9: mar | IL9: mer | IN9: jeu | IP9: ven | IR9: sam | IT9: dim | IY9: lun | JA9: mar | JC9: mer | JE9: jeu | JG9: ven | JI9: sam | JK9: dim | JM9: 31 | JN9: 2 | JO9: lun | JQ9: mar | JS9: mer | JU9: jeu | JW9: ven | JY9: sam | KA9: dim | KC9: 28 | KD9: 2 | KE9: lun | KG9: mar | KI9: mer | KK9: jeu | KM9: ven | KO9: sam | KQ9: dim | KV9: lun | KX9: mar | KZ9: mer | LB9: jeu | LD9: ven | LF9: sam | LH9: dim | LJ9: 31 | LK9: 2 | LL9: lun | LN9: mar | LP9: mer | LR9: jeu | LT9: ven | LV9: sam | LX9: dim | LZ9: 28 | MA9: 2 | MB9: lun | MD9: mar | MF9: mer | MH9: jeu | MJ9: ven | ML9: sam | MN9: dim | MS9: lun | MU9: mar | MW9: mer | MY9: jeu | NA9: ven | NC9: sam | NE9: dim | NG9: 31 | NH9: 2 | NI9: lun | NK9: mar | NM9: mer | NO9: jeu | NQ9: ven | NS9: sam | NU9: dim | NW9: 28 | NX9: 2 | NY9: lun | OA9: mar | OC9: mer | OE9: jeu | OG9: ven | OI9: sam | OK9: dim | OP9: lun | OR9: mar | OT9: mer | OV9: jeu | OX9: ven | OZ9: sam | PB9: dim | PD9: 31 | PE9: 2 | PF9: lun | PH9: mar | PJ9: mer | PL9: jeu | PN9: ven | PP9: sam | PR9: dim | PT9: 28 | PU9: 2 | PV9: lun | PX9: mar | PZ9: mer | QB9: jeu | QD9: ven | QF9: sam | QH9: dim | QN9: lun | QP9: mar | QR9: mer | QT9: jeu | QV9: ven | QX9: sam | QZ9: dim | RB9: 31 | RC9: 2 | RD9: lun | RF9: mar | RH9: mer | RJ9: jeu | RL9: ven | RN9: sam | RP9: dim | RR9: 28 | RS9: 2 | RT9: lun | RV9: mar | RX9: mer | RZ9: jeu | SB9: ven | SD9: sam | SF9: dim | SL9: lun | SN9: mar | SP9: mer | SR9: jeu | ST9: ven | SV9: sam | SX9: dim | SZ9: 31 | TA9: 2 | TB9: lun | TD9: mar | TF9: mer | TH9: jeu | TJ9: ven | TL9: sam | TN9: dim | TP9: 28 | TQ9: 2 | TR9: lun | TT9: mar | TV9: mer | TX9: jeu | TZ9: ven | UB9: sam | UD9: dim
